<?xml version="1.0" ?>
<!-- Generated using onshape-to-robot -->
<!-- OnShape https://cad.onshape.com/documents/db767f993257567c9d429d52/w/4a825d5c773cc58f8a017866/e/27e3da77599159011abb67dd -->
<mujoco model="2_dof">
    <compiler angle="radian" meshdir="assets" autolimits="false"/>
    <option noslip_iterations="1"/>
    <default>
        <default class="2_dof">
            <joint frictionloss="0.1" armature="0.005"/>
            <position kp="50" dampratio="1"/>
            <default class="visual">
                <geom type="mesh" contype="0" conaffinity="0" group="2"/>
            </default>
            <default class="collision">
                <geom group="3"/>
            </default>
        </default>
    </default>
    <worldbody>
        <!-- Link base -->
        <body name="base" pos="0 0 0" quat="1 0 0 0" childclass="2_dof">
            <inertial pos="-0.00171891 0.00210963 0.0148677" mass="0.414975" fullinertia="0.000104701 0.000105973 0.000148427 0 0 0"/>
            <!-- Part base -->
            <!-- Mesh base -->
            <geom type="mesh" class="visual" pos="0.0205595 -0.0199801 -0.000132298" quat="1 0 0 0" mesh="base" material="base_material"/>
            <!-- Mesh base -->
            <geom type="mesh" class="collision" pos="0.0205595 -0.0199801 -0.000132298" quat="1 0 0 0" mesh="base" material="base_material"/>
            <!-- Link cópia__5__de_peça2_poc_quadrupede -->
            <body name="cópia__5__de_peça2_poc_quadrupede" pos="-0.00171891 0.00210963 0.0298677" quat="1.70044e-17 0.707107 0.707107 2.54598e-17">
                <!-- Joint from base to cópia__5__de_peça2_poc_quadrupede -->
                <joint name="coxa" type="hinge"/>
                <inertial pos="1.73472e-18 0.0275 -0.0075" mass="0.0182237" fullinertia="7.48609e-06 7.54968e-07 7.55766e-06 -1.86114e-38 2.31786e-38 -2.06918e-38"/>
                <!-- Part cópia__5__de_peça2_poc_quadrupede -->
                <!-- Mesh cópia__5__de_peça2_poc_quadrupede -->
                <geom type="mesh" class="visual" pos="-0.015 -0.00883828 -0.015" quat="0.707107 -0.707107 -0 8.17103e-33" mesh="cópia__5__de_peça2_poc_quadrupede" material="cópia__5__de_peça2_poc_quadrupede_material"/>
                <!-- Mesh cópia__5__de_peça2_poc_quadrupede -->
                <geom type="mesh" class="collision" pos="-0.015 -0.00883828 -0.015" quat="0.707107 -0.707107 -0 8.17103e-33" mesh="cópia__5__de_peça2_poc_quadrupede" material="cópia__5__de_peça2_poc_quadrupede_material"/>
                <!-- Link cópia__3__de_peça2_poc_quadrupede -->
                <body name="cópia__3__de_peça2_poc_quadrupede" pos="-5.15193e-19 0.055 -0.015" quat="1 7.8209e-17 1.11022e-16 -6.05126e-17">
                    <!-- Joint from cópia__5__de_peça2_poc_quadrupede to cópia__3__de_peça2_poc_quadrupede -->
                    <joint name="pata" type="hinge"/>
                    <inertial pos="1.73472e-18 0.0275 -0.0075" mass="0.0182237" fullinertia="7.48609e-06 7.54968e-07 7.55766e-06 0 0 3.93793e-38"/>
                    <!-- Part cópia__3__de_peça2_poc_quadrupede -->
                    <!-- Mesh cópia__3__de_peça2_poc_quadrupede -->
                    <geom type="mesh" class="visual" pos="-0.015 0.0638383 0" quat="0.707107 0.707107 -0 -0" mesh="cópia__3__de_peça2_poc_quadrupede" material="cópia__3__de_peça2_poc_quadrupede_material"/>
                    <!-- Mesh cópia__3__de_peça2_poc_quadrupede -->
                    <geom type="mesh" class="collision" pos="-0.015 0.0638383 0" quat="0.707107 0.707107 -0 -0" mesh="cópia__3__de_peça2_poc_quadrupede" material="cópia__3__de_peça2_poc_quadrupede_material"/>
                    <!-- Frame ee (dummy link + fixed joint) -->
                    <site name="ee" pos="-1.53048e-18 0.055 -0.017" quat="0.5 -0.5 -0.5 0.5"/>
                </body>
            </body>
        </body>
    </worldbody>
    <asset>
        <mesh file="cópia__5__de_peça2_poc_quadrupede.stl"/>
        <mesh file="base.stl"/>
        <mesh file="cópia__3__de_peça2_poc_quadrupede.stl"/>
        <material name="base_material" rgba="0.615686 0.811765 0.929412 1"/>
        <material name="cópia__5__de_peça2_poc_quadrupede_material" rgba="0.0352941 0 0.968627 1"/>
        <material name="cópia__3__de_peça2_poc_quadrupede_material" rgba="1 0.156863 0.121569 1"/>
    </asset>
    <actuator>
        <position class="2_dof" name="pata" joint="pata"/>
        <position class="2_dof" name="coxa" joint="coxa"/>
    </actuator>
    <equality/>
</mujoco>
